File: preliminar_analysis_data/PostData1.0.txt
name, value (cm), Max Mises Stress (Pa), Max Displacement (cm), V (cm^3), SA (cm^2), SA:V (1/cm)
Model-1, L, 14.000, 425437952, 0.3654, 2.567, 58.904, 22.94751
Model-2, L, 20.000, 420857824, 0.5003, 3.551, 79.742, 22.45343
Model-3, L11, 0.400, 388064928, 0.3420, 3.110, 69.576, 22.37115
Model-4, L11, 0.600, 439014592, 0.5202, 3.013, 69.103, 22.93303
Model-5, W, 2.000, 546544768, 0.4571, 2.683, 61.222, 22.81815
Model-6, W, 3.000, 387150688, 0.4028, 3.428, 77.208, 22.51987
Model-7, W3, 0.200, 413800320, 0.4186, 2.838, 65.076, 22.93376
Model-8, W3, 0.400, 409236704, 0.4114, 3.283, 74.074, 22.56318
Model-9, W4, 0.200, 397939712, 0.4022, 2.848, 65.220, 22.90221
Model-10, W4, 0.500, 405101536, 0.4245, 3.261, 73.357, 22.49479
Model-11, T, 0.300, 764232128, 1.0144, 2.055, 61.526, 29.94655
Model-12, T, 0.500, 306558624, 0.2177, 4.206, 76.741, 18.24449
Model-13, T1, 0.100, 949523328, 0.9806, 2.990, 68.552, 22.92564
Model-14, T1, 0.400, 336543392, 0.2898, 3.101, 70.419, 22.70808
Model-15, h4, 1.200, 375826144, 0.2958, 3.007, 67.186, 22.34095
Model-16, h4, 2.000, 541993728, 0.5982, 3.118, 71.630, 22.97118
Model-17, h7, 0.000, 561369216, 0.8718, 3.068, 69.890, 22.78044
Model-18, h7, 0.600, 359629056, 0.5184, 3.049, 68.678, 22.52794
Model-19, T2, 0.150, 622815488, 0.5898, 2.123, 71.357, 33.61896
Model-20, T2, 0.350, 409829088, 0.3829, 3.873, 67.698, 17.48172
Model-21, T3, 0.150, 437217152, 0.5054, 2.937, 69.320, 23.60290
Model-22, T3, 0.350, 385707456, 0.3685, 3.173, 69.123, 21.78303